<?xml version="1.0"?>
<sdf version="1.5"><model name="gen__2"><pose>1.000000e+00 1.000000e+00 5.000000e-02 0.000000e+00 -0.000000e+00 0.000000e+00</pose>
<link name="link_component_node-0__box"><pose>-3.491176e-03 -2.120136e-03 -3.009157e-20 0.000000e+00 -0.000000e+00 0.000000e+00</pose>
<visual name="component_node-0__box_visual"><pose>3.491176e-03 2.120136e-03 3.009157e-20 0.000000e+00 -0.000000e+00 0.000000e+00</pose>
<material><ambient>0.45 0.72 0.48 1.00</ambient><diffuse>0.45 0.72 0.48 1.00</diffuse><specular>0.1 0.1 0.1 1.00</specular></material>
<geometry><mesh><uri>model://rg_robot/meshes/CoreComponent.dae</uri></mesh></geometry></visual>
<collision name="component_node-0__box_collision"><pose>3.491176e-03 2.120136e-03 3.009157e-20 0.000000e+00 -0.000000e+00 0.000000e+00</pose>
<surface><contact><ode><kd>3.333333e+06</kd><kp>9.000000e+04</kp></ode></contact>
<friction><ode><mu>1.000000e+00</mu>
<mu2>1.000000e+00</mu2>
<slip1>1.000000e-02</slip1>
<slip2>1.000000e-02</slip2></ode>
<bullet><friction>1.000000e+00</friction>
<friction2>1.000000e+00</friction2></bullet></friction></surface>
<geometry><box><size>9.000000e-02 9.000000e-02 4.500000e-02</size></box></geometry></collision>
<sensor type="imu" name="node-0-imu_sensor"><pose>3.491176e-03 2.120136e-03 3.009157e-20 0.000000e+00 -0.000000e+00 0.000000e+00</pose>
<update_rate>8.000000e+00</update_rate>
<always_on>1</always_on></sensor>
<visual name="component_node-1__box_visual"><pose>3.491176e-03 -6.337986e-02 3.009157e-20 0.000000e+00 -0.000000e+00 1.570796e+00</pose>
<material><ambient>0.50 0.65 0.96 1.00</ambient><diffuse>0.50 0.65 0.96 1.00</diffuse><specular>0.1 0.1 0.1 1.00</specular></material>
<geometry><mesh><uri>model://rg_robot/meshes/FixedBrick.dae</uri></mesh></geometry></visual>
<collision name="component_node-1__box_collision"><pose>3.491176e-03 -6.337986e-02 3.009157e-20 0.000000e+00 -0.000000e+00 1.570796e+00</pose>
<surface><contact><ode><kd>3.333333e+06</kd><kp>9.000000e+04</kp></ode></contact>
<friction><ode><mu>1.000000e+00</mu>
<mu2>1.000000e+00</mu2>
<slip1>1.000000e-02</slip1>
<slip2>1.000000e-02</slip2></ode>
<bullet><friction>1.000000e+00</friction>
<friction2>1.000000e+00</friction2></bullet></friction></surface>
<geometry><box><size>4.100000e-02 4.100000e-02 3.550000e-02</size></box></geometry></collision>
<visual name="component_node-2__root_visual"><pose>3.491176e-03 4.787014e-02 -1.364419e-19 1.570796e+00 3.330669e-16 1.570796e+00</pose>
<material><ambient>0.45 0.72 0.48 1.00</ambient><diffuse>0.45 0.72 0.48 1.00</diffuse><specular>0.1 0.1 0.1 1.00</specular></material>
<geometry><box><size>1.500000e-03 3.400000e-02 3.400000e-02</size></box></geometry></visual>
<collision name="component_node-2__root_collision"><pose>3.491176e-03 4.787014e-02 -1.364419e-19 1.570796e+00 3.330669e-16 1.570796e+00</pose>
<surface><contact><ode><kd>3.333333e+06</kd><kp>9.000000e+04</kp></ode></contact>
<friction><ode><mu>1.000000e+00</mu>
<mu2>1.000000e+00</mu2>
<slip1>1.000000e-02</slip1>
<slip2>1.000000e-02</slip2></ode>
<bullet><friction>1.000000e+00</friction>
<friction2>1.000000e+00</friction2></bullet></friction></surface>
<geometry><box><size>1.500000e-03 3.400000e-02 3.400000e-02</size></box></geometry></collision>
<visual name="component_node-2__frame_frame_visual"><pose>3.491176e-03 5.772014e-02 -2.323581e-18 1.570796e+00 3.330669e-16 1.570796e+00</pose>
<material><ambient>0.45 0.72 0.48 1.00</ambient><diffuse>0.45 0.72 0.48 1.00</diffuse><specular>0.1 0.1 0.1 1.00</specular></material>
<geometry><mesh><uri>model://rg_robot/meshes/ActiveHinge_Frame.dae</uri></mesh></geometry></visual>
<collision name="component_node-2__frame_collision"><pose>3.491176e-03 5.772014e-02 -2.323581e-18 1.570796e+00 3.330669e-16 1.570796e+00</pose>
<surface><contact><ode><kd>3.333333e+06</kd><kp>9.000000e+04</kp></ode></contact>
<friction><ode><mu>1.000000e+00</mu>
<mu2>1.000000e+00</mu2>
<slip1>1.000000e-02</slip1>
<slip2>1.000000e-02</slip2></ode>
<bullet><friction>1.000000e+00</friction>
<friction2>1.000000e+00</friction2></bullet></friction></surface>
<geometry><box><size>1.800000e-02 3.400000e-02 1.000000e-02</size></box></geometry></collision>
<visual name="component_node-5__root_visual"><pose>4.924118e-02 2.120136e-03 3.009157e-20 -1.570796e+00 0.000000e+00 0.000000e+00</pose>
<material><ambient>0.45 0.72 0.48 1.00</ambient><diffuse>0.45 0.72 0.48 1.00</diffuse><specular>0.1 0.1 0.1 1.00</specular></material>
<geometry><box><size>1.500000e-03 3.400000e-02 3.400000e-02</size></box></geometry></visual>
<collision name="component_node-5__root_collision"><pose>4.924118e-02 2.120136e-03 3.009157e-20 -1.570796e+00 0.000000e+00 0.000000e+00</pose>
<surface><contact><ode><kd>3.333333e+06</kd><kp>9.000000e+04</kp></ode></contact>
<friction><ode><mu>1.000000e+00</mu>
<mu2>1.000000e+00</mu2>
<slip1>1.000000e-02</slip1>
<slip2>1.000000e-02</slip2></ode>
<bullet><friction>1.000000e+00</friction>
<friction2>1.000000e+00</friction2></bullet></friction></surface>
<geometry><box><size>1.500000e-03 3.400000e-02 3.400000e-02</size></box></geometry></collision>
<visual name="component_node-5__frame_frame_visual"><pose>5.909118e-02 2.120136e-03 3.009157e-20 -1.570796e+00 0.000000e+00 0.000000e+00</pose>
<material><ambient>0.45 0.72 0.48 1.00</ambient><diffuse>0.45 0.72 0.48 1.00</diffuse><specular>0.1 0.1 0.1 1.00</specular></material>
<geometry><mesh><uri>model://rg_robot/meshes/ActiveHinge_Frame.dae</uri></mesh></geometry></visual>
<collision name="component_node-5__frame_collision"><pose>5.909118e-02 2.120136e-03 3.009157e-20 -1.570796e+00 0.000000e+00 0.000000e+00</pose>
<surface><contact><ode><kd>3.333333e+06</kd><kp>9.000000e+04</kp></ode></contact>
<friction><ode><mu>1.000000e+00</mu>
<mu2>1.000000e+00</mu2>
<slip1>1.000000e-02</slip1>
<slip2>1.000000e-02</slip2></ode>
<bullet><friction>1.000000e+00</friction>
<friction2>1.000000e+00</friction2></bullet></friction></surface>
<geometry><box><size>1.800000e-02 3.400000e-02 1.000000e-02</size></box></geometry></collision>
<collision name="component_node-9__tail_collision"><pose>-4.225882e-02 2.120136e-03 3.009157e-20 1.570796e+00 -0.000000e+00 0.000000e+00</pose>
<surface><contact><ode><kd>3.333333e+06</kd><kp>9.000000e+04</kp></ode></contact>
<friction><ode><mu>1.000000e+00</mu>
<mu2>1.000000e+00</mu2>
<slip1>1.000000e-02</slip1>
<slip2>1.000000e-02</slip2></ode>
<bullet><friction>1.000000e+00</friction>
<friction2>1.000000e+00</friction2></bullet></friction></surface>
<geometry><box><size>1.500000e-03 3.400000e-02 3.400000e-02</size></box></geometry></collision>
<visual name="component_node-9__servo_servo_visual"><pose>-5.535882e-02 2.120136e-03 3.009157e-20 1.570796e+00 -0.000000e+00 0.000000e+00</pose>
<material><ambient>0.45 0.72 0.48 1.00</ambient><diffuse>0.45 0.72 0.48 1.00</diffuse><specular>0.1 0.1 0.1 1.00</specular></material>
<geometry><mesh><uri>model://rg_robot/meshes/ActiveCardanHinge_Servo_Holder.dae</uri></mesh></geometry></visual>
<collision name="component_node-9__servo_collision"><pose>-5.535882e-02 2.120136e-03 3.009157e-20 1.570796e+00 -0.000000e+00 0.000000e+00</pose>
<surface><contact><ode><kd>3.333333e+06</kd><kp>9.000000e+04</kp></ode></contact>
<friction><ode><mu>1.000000e+00</mu>
<mu2>1.000000e+00</mu2>
<slip1>1.000000e-02</slip1>
<slip2>1.000000e-02</slip2></ode>
<bullet><friction>1.000000e+00</friction>
<friction2>1.000000e+00</friction2></bullet></friction></surface>
<geometry><box><size>2.450000e-02 3.400000e-02 1.000000e-02</size></box></geometry></collision>
<inertial><mass>1.326000e-01</mass><inertia><ixx>1.445517e-04</ixx><ixy>9.814744e-07</ixy><ixz>-7.751277e-23</ixz><iyy>1.452945e-04</iyy><iyz>1.920606e-22</iyz><izz>2.510864e-04</izz></inertia></inertial>
<self_collide>True</self_collide></link>
<link name="link_component_node-2__servo"><pose>5.003566e-35 8.270000e-02 -8.371082e-18 0.000000e+00 -0.000000e+00 0.000000e+00</pose>
<visual name="component_node-2__servo_servo_visual"><pose>-5.003566e-35 -1.385000e-02 3.075318e-18 1.570796e+00 3.330669e-16 1.570796e+00</pose>
<material><ambient>0.45 0.72 0.48 1.00</ambient><diffuse>0.45 0.72 0.48 1.00</diffuse><specular>0.1 0.1 0.1 1.00</specular></material>
<geometry><mesh><uri>model://rg_robot/meshes/ActiveCardanHinge_Servo_Holder.dae</uri></mesh></geometry></visual>
<collision name="component_node-2__servo_collision"><pose>-5.003566e-35 -1.385000e-02 3.075318e-18 1.570796e+00 3.330669e-16 1.570796e+00</pose>
<surface><contact><ode><kd>3.333333e+06</kd><kp>9.000000e+04</kp></ode></contact>
<friction><ode><mu>1.000000e+00</mu>
<mu2>1.000000e+00</mu2>
<slip1>1.000000e-02</slip1>
<slip2>1.000000e-02</slip2></ode>
<bullet><friction>1.000000e+00</friction>
<friction2>1.000000e+00</friction2></bullet></friction></surface>
<geometry><box><size>2.450000e-02 3.400000e-02 1.000000e-02</size></box></geometry></collision>
<collision name="component_node-2__tail_collision"><pose>-5.003566e-35 -7.500000e-04 1.665335e-19 1.570796e+00 3.330669e-16 1.570796e+00</pose>
<surface><contact><ode><kd>3.333333e+06</kd><kp>9.000000e+04</kp></ode></contact>
<friction><ode><mu>1.000000e+00</mu>
<mu2>1.000000e+00</mu2>
<slip1>1.000000e-02</slip1>
<slip2>1.000000e-02</slip2></ode>
<bullet><friction>1.000000e+00</friction>
<friction2>1.000000e+00</friction2></bullet></friction></surface>
<geometry><box><size>1.500000e-03 3.400000e-02 3.400000e-02</size></box></geometry></collision>
<collision name="component_node-3__tail_collision"><pose>-4.079120e-35 7.500000e-04 -1.665335e-19 3.141593e+00 -2.220446e-16 -1.570796e+00</pose>
<surface><contact><ode><kd>3.333333e+06</kd><kp>9.000000e+04</kp></ode></contact>
<friction><ode><mu>1.000000e+00</mu>
<mu2>1.000000e+00</mu2>
<slip1>1.000000e-02</slip1>
<slip2>1.000000e-02</slip2></ode>
<bullet><friction>1.000000e+00</friction>
<friction2>1.000000e+00</friction2></bullet></friction></surface>
<geometry><box><size>1.500000e-03 3.400000e-02 3.400000e-02</size></box></geometry></collision>
<visual name="component_node-3__servo_servo_visual"><pose>1.206788e-34 1.385000e-02 -3.075318e-18 3.141593e+00 -2.220446e-16 -1.570796e+00</pose>
<material><ambient>0.25 0.93 0.90 1.00</ambient><diffuse>0.25 0.93 0.90 1.00</diffuse><specular>0.1 0.1 0.1 1.00</specular></material>
<geometry><mesh><uri>model://rg_robot/meshes/ActiveCardanHinge_Servo_Holder.dae</uri></mesh></geometry></visual>
<collision name="component_node-3__servo_collision"><pose>1.206788e-34 1.385000e-02 -3.075318e-18 3.141593e+00 -2.220446e-16 -1.570796e+00</pose>
<surface><contact><ode><kd>3.333333e+06</kd><kp>9.000000e+04</kp></ode></contact>
<friction><ode><mu>1.000000e+00</mu>
<mu2>1.000000e+00</mu2>
<slip1>1.000000e-02</slip1>
<slip2>1.000000e-02</slip2></ode>
<bullet><friction>1.000000e+00</friction>
<friction2>1.000000e+00</friction2></bullet></friction></surface>
<geometry><box><size>2.450000e-02 3.400000e-02 1.000000e-02</size></box></geometry></collision>
<inertial><mass>3.200000e-02</mass><inertia><ixx>6.654347e-06</ixx><ixy>-2.543151e-22</ixy><ixz>-2.212489e-22</ixz><iyy>4.581333e-06</iyy><iyz>2.059863e-22</iyz><izz>6.654347e-06</izz></inertia></inertial>
<self_collide>True</self_collide></link>
<link name="link_component_node-3__frame"><pose>4.526505e-34 1.307875e-01 -1.295676e-17 0.000000e+00 -0.000000e+00 0.000000e+00</pose>
<visual name="component_node-3__frame_frame_visual"><pose>-1.186172e-34 -2.098750e-02 -1.431730e-18 3.141593e+00 -2.220446e-16 -1.570796e+00</pose>
<material><ambient>0.25 0.93 0.90 1.00</ambient><diffuse>0.25 0.93 0.90 1.00</diffuse><specular>0.1 0.1 0.1 1.00</specular></material>
<geometry><mesh><uri>model://rg_robot/meshes/ActiveHinge_Frame.dae</uri></mesh></geometry></visual>
<collision name="component_node-3__frame_collision"><pose>-1.186172e-34 -2.098750e-02 -1.431730e-18 3.141593e+00 -2.220446e-16 -1.570796e+00</pose>
<surface><contact><ode><kd>3.333333e+06</kd><kp>9.000000e+04</kp></ode></contact>
<friction><ode><mu>1.000000e+00</mu>
<mu2>1.000000e+00</mu2>
<slip1>1.000000e-02</slip1>
<slip2>1.000000e-02</slip2></ode>
<bullet><friction>1.000000e+00</friction>
<friction2>1.000000e+00</friction2></bullet></friction></surface>
<geometry><box><size>1.800000e-02 3.400000e-02 1.000000e-02</size></box></geometry></collision>
<visual name="component_node-3__root_visual"><pose>2.793436e-36 -1.113750e-02 -3.618869e-18 3.141593e+00 -2.220446e-16 -1.570796e+00</pose>
<material><ambient>0.25 0.93 0.90 1.00</ambient><diffuse>0.25 0.93 0.90 1.00</diffuse><specular>0.1 0.1 0.1 1.00</specular></material>
<geometry><box><size>1.500000e-03 3.400000e-02 3.400000e-02</size></box></geometry></visual>
<collision name="component_node-3__root_collision"><pose>2.793436e-36 -1.113750e-02 -3.618869e-18 3.141593e+00 -2.220446e-16 -1.570796e+00</pose>
<surface><contact><ode><kd>3.333333e+06</kd><kp>9.000000e+04</kp></ode></contact>
<friction><ode><mu>1.000000e+00</mu>
<mu2>1.000000e+00</mu2>
<slip1>1.000000e-02</slip1>
<slip2>1.000000e-02</slip2></ode>
<bullet><friction>1.000000e+00</friction>
<friction2>1.000000e+00</friction2></bullet></friction></surface>
<geometry><box><size>1.500000e-03 3.400000e-02 3.400000e-02</size></box></geometry></collision>
<visual name="component_node-4__box_visual"><pose>1.203790e-35 1.011250e-02 2.651976e-18 -3.140185e-16 3.140185e-16 -1.570796e+00</pose>
<material><ambient>0.50 0.65 0.96 1.00</ambient><diffuse>0.50 0.65 0.96 1.00</diffuse><specular>0.1 0.1 0.1 1.00</specular></material>
<geometry><mesh><uri>model://rg_robot/meshes/FixedBrick.dae</uri></mesh></geometry></visual>
<collision name="component_node-4__box_collision"><pose>1.203790e-35 1.011250e-02 2.651976e-18 -3.140185e-16 3.140185e-16 -1.570796e+00</pose>
<surface><contact><ode><kd>3.333333e+06</kd><kp>9.000000e+04</kp></ode></contact>
<friction><ode><mu>1.000000e+00</mu>
<mu2>1.000000e+00</mu2>
<slip1>1.000000e-02</slip1>
<slip2>1.000000e-02</slip2></ode>
<bullet><friction>1.000000e+00</friction>
<friction2>1.000000e+00</friction2></bullet></friction></surface>
<geometry><box><size>4.100000e-02 4.100000e-02 3.550000e-02</size></box></geometry></collision>
<inertial><mass>1.840000e-02</mass><inertia><ixx>5.658065e-06</ixx><ixy>-2.587799e-37</ixy><ixz>1.123048e-22</ixz><iyy>3.974329e-06</iyy><iyz>-8.485106e-22</iyz><izz>6.121302e-06</izz></inertia></inertial>
<self_collide>True</self_collide></link>
<joint type="revolute" name="joint_link_component_node-2__servo_link_component_node-3__frame"><pose>-1.802469e-34 -2.598750e-02 -3.215068e-19 3.141593e+00 -2.220446e-16 -1.570796e+00</pose>
<parent>link_component_node-2__servo</parent>
<child>link_component_node-3__frame</child>
<axis><xyz>0.000000e+00 1.000000e+00 0.000000e+00</xyz>
<use_parent_model_frame>0</use_parent_model_frame>
<limit><lower>-7.853982e-01</lower>
<upper>7.853982e-01</upper>
<effort>1.765800e-01</effort>
<velocity>5.235988e+00</velocity></limit></axis></joint>
<joint type="revolute" name="joint_link_component_node-2__servo_link_component_node-0__box"><pose>3.491176e-03 6.272014e-02 -3.433804e-18 1.570796e+00 2.220446e-16 1.570796e+00</pose>
<parent>link_component_node-2__servo</parent>
<child>link_component_node-0__box</child>
<axis><xyz>0.000000e+00 1.000000e+00 0.000000e+00</xyz>
<use_parent_model_frame>0</use_parent_model_frame>
<limit><lower>-7.853982e-01</lower>
<upper>7.853982e-01</upper>
<effort>1.765800e-01</effort>
<velocity>5.235988e+00</velocity></limit></axis></joint>
<link name="link_component_node-5__servo"><pose>7.807479e-02 0.000000e+00 0.000000e+00 0.000000e+00 -0.000000e+00 0.000000e+00</pose>
<visual name="component_node-5__servo_servo_visual"><pose>-9.224793e-03 0.000000e+00 0.000000e+00 -1.570796e+00 0.000000e+00 0.000000e+00</pose>
<material><ambient>0.45 0.72 0.48 1.00</ambient><diffuse>0.45 0.72 0.48 1.00</diffuse><specular>0.1 0.1 0.1 1.00</specular></material>
<geometry><mesh><uri>model://rg_robot/meshes/ActiveCardanHinge_Servo_Holder.dae</uri></mesh></geometry></visual>
<collision name="component_node-5__servo_collision"><pose>-9.224793e-03 0.000000e+00 0.000000e+00 -1.570796e+00 0.000000e+00 0.000000e+00</pose>
<surface><contact><ode><kd>3.333333e+06</kd><kp>9.000000e+04</kp></ode></contact>
<friction><ode><mu>1.000000e+00</mu>
<mu2>1.000000e+00</mu2>
<slip1>1.000000e-02</slip1>
<slip2>1.000000e-02</slip2></ode>
<bullet><friction>1.000000e+00</friction>
<friction2>1.000000e+00</friction2></bullet></friction></surface>
<geometry><box><size>2.450000e-02 3.400000e-02 1.000000e-02</size></box></geometry></collision>
<collision name="component_node-5__tail_collision"><pose>3.875207e-03 0.000000e+00 0.000000e+00 -1.570796e+00 0.000000e+00 0.000000e+00</pose>
<surface><contact><ode><kd>3.333333e+06</kd><kp>9.000000e+04</kp></ode></contact>
<friction><ode><mu>1.000000e+00</mu>
<mu2>1.000000e+00</mu2>
<slip1>1.000000e-02</slip1>
<slip2>1.000000e-02</slip2></ode>
<bullet><friction>1.000000e+00</friction>
<friction2>1.000000e+00</friction2></bullet></friction></surface>
<geometry><box><size>1.500000e-03 3.400000e-02 3.400000e-02</size></box></geometry></collision>
<visual name="component_node-6__root_visual"><pose>5.375207e-03 0.000000e+00 0.000000e+00 3.141593e+00 -0.000000e+00 0.000000e+00</pose>
<material><ambient>0.45 0.72 0.48 1.00</ambient><diffuse>0.45 0.72 0.48 1.00</diffuse><specular>0.1 0.1 0.1 1.00</specular></material>
<geometry><box><size>1.500000e-03 3.400000e-02 3.400000e-02</size></box></geometry></visual>
<collision name="component_node-6__root_collision"><pose>5.375207e-03 0.000000e+00 0.000000e+00 3.141593e+00 -0.000000e+00 0.000000e+00</pose>
<surface><contact><ode><kd>3.333333e+06</kd><kp>9.000000e+04</kp></ode></contact>
<friction><ode><mu>1.000000e+00</mu>
<mu2>1.000000e+00</mu2>
<slip1>1.000000e-02</slip1>
<slip2>1.000000e-02</slip2></ode>
<bullet><friction>1.000000e+00</friction>
<friction2>1.000000e+00</friction2></bullet></friction></surface>
<geometry><box><size>1.500000e-03 3.400000e-02 3.400000e-02</size></box></geometry></collision>
<visual name="component_node-6__frame_frame_visual"><pose>1.522521e-02 0.000000e+00 0.000000e+00 3.141593e+00 -0.000000e+00 0.000000e+00</pose>
<material><ambient>0.45 0.72 0.48 1.00</ambient><diffuse>0.45 0.72 0.48 1.00</diffuse><specular>0.1 0.1 0.1 1.00</specular></material>
<geometry><mesh><uri>model://rg_robot/meshes/ActiveHinge_Frame.dae</uri></mesh></geometry></visual>
<collision name="component_node-6__frame_collision"><pose>1.522521e-02 0.000000e+00 0.000000e+00 3.141593e+00 -0.000000e+00 0.000000e+00</pose>
<surface><contact><ode><kd>3.333333e+06</kd><kp>9.000000e+04</kp></ode></contact>
<friction><ode><mu>1.000000e+00</mu>
<mu2>1.000000e+00</mu2>
<slip1>1.000000e-02</slip1>
<slip2>1.000000e-02</slip2></ode>
<bullet><friction>1.000000e+00</friction>
<friction2>1.000000e+00</friction2></bullet></friction></surface>
<geometry><box><size>1.800000e-02 3.400000e-02 1.000000e-02</size></box></geometry></collision>
<inertial><mass>2.420000e-02</mass><inertia><ixx>3.764933e-06</ixx><ixy>0.000000e+00</ixy><ixz>0.000000e+00</ixz><iyy>4.062289e-06</iyy><iyz>-2.579270e-22</iyz><izz>3.375889e-06</izz></inertia></inertial>
<self_collide>True</self_collide></link>
<link name="link_component_node-6__servo"><pose>1.300493e-01 1.085071e-02 -1.096620e-17 0.000000e+00 -0.000000e+00 0.000000e+00</pose>
<visual name="component_node-6__servo_servo_visual"><pose>-2.349929e-02 -1.085071e-02 1.096620e-17 3.141593e+00 -0.000000e+00 0.000000e+00</pose>
<material><ambient>0.45 0.72 0.48 1.00</ambient><diffuse>0.45 0.72 0.48 1.00</diffuse><specular>0.1 0.1 0.1 1.00</specular></material>
<geometry><mesh><uri>model://rg_robot/meshes/ActiveCardanHinge_Servo_Holder.dae</uri></mesh></geometry></visual>
<collision name="component_node-6__servo_collision"><pose>-2.349929e-02 -1.085071e-02 1.096620e-17 3.141593e+00 -0.000000e+00 0.000000e+00</pose>
<surface><contact><ode><kd>3.333333e+06</kd><kp>9.000000e+04</kp></ode></contact>
<friction><ode><mu>1.000000e+00</mu>
<mu2>1.000000e+00</mu2>
<slip1>1.000000e-02</slip1>
<slip2>1.000000e-02</slip2></ode>
<bullet><friction>1.000000e+00</friction>
<friction2>1.000000e+00</friction2></bullet></friction></surface>
<geometry><box><size>2.450000e-02 3.400000e-02 1.000000e-02</size></box></geometry></collision>
<collision name="component_node-6__tail_collision"><pose>-1.039929e-02 -1.085071e-02 1.096620e-17 3.141593e+00 -0.000000e+00 0.000000e+00</pose>
<surface><contact><ode><kd>3.333333e+06</kd><kp>9.000000e+04</kp></ode></contact>
<friction><ode><mu>1.000000e+00</mu>
<mu2>1.000000e+00</mu2>
<slip1>1.000000e-02</slip1>
<slip2>1.000000e-02</slip2></ode>
<bullet><friction>1.000000e+00</friction>
<friction2>1.000000e+00</friction2></bullet></friction></surface>
<geometry><box><size>1.500000e-03 3.400000e-02 3.400000e-02</size></box></geometry></collision>
<visual name="component_node-7__box_visual"><pose>1.085071e-02 -1.085071e-02 1.096620e-17 1.010643e-15 -0.000000e+00 3.141593e+00</pose>
<material><ambient>0.25 0.93 0.90 1.00</ambient><diffuse>0.25 0.93 0.90 1.00</diffuse><specular>0.1 0.1 0.1 1.00</specular></material>
<geometry><mesh><uri>model://rg_robot/meshes/FixedBrick.dae</uri></mesh></geometry></visual>
<collision name="component_node-7__box_collision"><pose>1.085071e-02 -1.085071e-02 1.096620e-17 1.010643e-15 -0.000000e+00 3.141593e+00</pose>
<surface><contact><ode><kd>3.333333e+06</kd><kp>9.000000e+04</kp></ode></contact>
<friction><ode><mu>1.000000e+00</mu>
<mu2>1.000000e+00</mu2>
<slip1>1.000000e-02</slip1>
<slip2>1.000000e-02</slip2></ode>
<bullet><friction>1.000000e+00</friction>
<friction2>1.000000e+00</friction2></bullet></friction></surface>
<geometry><box><size>4.100000e-02 4.100000e-02 3.550000e-02</size></box></geometry></collision>
<collision name="component_node-8__tail_collision"><pose>1.085071e-02 1.039929e-02 -1.050997e-17 -3.141593e+00 -1.010643e-15 -1.570796e+00</pose>
<surface><contact><ode><kd>3.333333e+06</kd><kp>9.000000e+04</kp></ode></contact>
<friction><ode><mu>1.000000e+00</mu>
<mu2>1.000000e+00</mu2>
<slip1>1.000000e-02</slip1>
<slip2>1.000000e-02</slip2></ode>
<bullet><friction>1.000000e+00</friction>
<friction2>1.000000e+00</friction2></bullet></friction></surface>
<geometry><box><size>1.500000e-03 3.400000e-02 3.400000e-02</size></box></geometry></collision>
<visual name="component_node-8__servo_servo_visual"><pose>1.085071e-02 2.349929e-02 -2.374939e-17 -3.141593e+00 -1.010643e-15 -1.570796e+00</pose>
<material><ambient>0.25 0.93 0.90 1.00</ambient><diffuse>0.25 0.93 0.90 1.00</diffuse><specular>0.1 0.1 0.1 1.00</specular></material>
<geometry><mesh><uri>model://rg_robot/meshes/ActiveCardanHinge_Servo_Holder.dae</uri></mesh></geometry></visual>
<collision name="component_node-8__servo_collision"><pose>1.085071e-02 2.349929e-02 -2.374939e-17 -3.141593e+00 -1.010643e-15 -1.570796e+00</pose>
<surface><contact><ode><kd>3.333333e+06</kd><kp>9.000000e+04</kp></ode></contact>
<friction><ode><mu>1.000000e+00</mu>
<mu2>1.000000e+00</mu2>
<slip1>1.000000e-02</slip1>
<slip2>1.000000e-02</slip2></ode>
<bullet><friction>1.000000e+00</friction>
<friction2>1.000000e+00</friction2></bullet></friction></surface>
<geometry><box><size>2.450000e-02 3.400000e-02 1.000000e-02</size></box></geometry></collision>
<inertial><mass>4.220000e-02</mass><inertia><ixx>1.480326e-05</ixx><ixy>-4.968541e-06</ixy><ixz>4.924429e-21</ixz><iyy>1.480326e-05</iyy><iyz>9.669361e-21</iyz><izz>2.446677e-05</izz></inertia></inertial>
<self_collide>True</self_collide></link>
<link name="link_component_node-8__frame"><pose>1.409000e-01 5.600854e-02 -5.660464e-17 0.000000e+00 -0.000000e+00 0.000000e+00</pose>
<visual name="component_node-8__frame_frame_visual"><pose>0.000000e+00 -8.408537e-03 8.498029e-18 -3.141593e+00 -1.010643e-15 -1.570796e+00</pose>
<material><ambient>0.25 0.93 0.90 1.00</ambient><diffuse>0.25 0.93 0.90 1.00</diffuse><specular>0.1 0.1 0.1 1.00</specular></material>
<geometry><mesh><uri>model://rg_robot/meshes/ActiveHinge_Frame.dae</uri></mesh></geometry></visual>
<collision name="component_node-8__frame_collision"><pose>0.000000e+00 -8.408537e-03 8.498029e-18 -3.141593e+00 -1.010643e-15 -1.570796e+00</pose>
<surface><contact><ode><kd>3.333333e+06</kd><kp>9.000000e+04</kp></ode></contact>
<friction><ode><mu>1.000000e+00</mu>
<mu2>1.000000e+00</mu2>
<slip1>1.000000e-02</slip1>
<slip2>1.000000e-02</slip2></ode>
<bullet><friction>1.000000e+00</friction>
<friction2>1.000000e+00</friction2></bullet></friction></surface>
<geometry><box><size>1.800000e-02 3.400000e-02 1.000000e-02</size></box></geometry></collision>
<visual name="component_node-8__root_visual"><pose>0.000000e+00 1.441463e-03 -1.456805e-18 -3.141593e+00 -1.010643e-15 -1.570796e+00</pose>
<material><ambient>0.25 0.93 0.90 1.00</ambient><diffuse>0.25 0.93 0.90 1.00</diffuse><specular>0.1 0.1 0.1 1.00</specular></material>
<geometry><box><size>1.500000e-03 3.400000e-02 3.400000e-02</size></box></geometry></visual>
<collision name="component_node-8__root_collision"><pose>0.000000e+00 1.441463e-03 -1.456805e-18 -3.141593e+00 -1.010643e-15 -1.570796e+00</pose>
<surface><contact><ode><kd>3.333333e+06</kd><kp>9.000000e+04</kp></ode></contact>
<friction><ode><mu>1.000000e+00</mu>
<mu2>1.000000e+00</mu2>
<slip1>1.000000e-02</slip1>
<slip2>1.000000e-02</slip2></ode>
<bullet><friction>1.000000e+00</friction>
<friction2>1.000000e+00</friction2></bullet></friction></surface>
<geometry><box><size>1.500000e-03 3.400000e-02 3.400000e-02</size></box></geometry></collision>
<inertial><mass>8.200000e-03</mass><inertia><ixx>8.174347e-07</ixx><ixy>6.017547e-37</ixy><ixz>-1.293227e-23</ixz><iyy>1.474267e-06</iyy><iyz>-5.570987e-22</iyz><izz>9.230347e-07</izz></inertia></inertial>
<self_collide>True</self_collide></link>
<joint type="revolute" name="joint_link_component_node-6__servo_link_component_node-8__frame"><pose>-1.604917e-33 -1.340854e-02 1.355124e-17 -3.141593e+00 -1.010643e-15 -1.570796e+00</pose>
<parent>link_component_node-6__servo</parent>
<child>link_component_node-8__frame</child>
<axis><xyz>0.000000e+00 1.000000e+00 0.000000e+00</xyz>
<use_parent_model_frame>0</use_parent_model_frame>
<limit><lower>-7.853982e-01</lower>
<upper>7.853982e-01</upper>
<effort>1.765800e-01</effort>
<velocity>5.235988e+00</velocity></limit></axis></joint>
<joint type="revolute" name="joint_link_component_node-6__servo_link_component_node-5__servo"><pose>2.022521e-02 0.000000e+00 0.000000e+00 3.141593e+00 -0.000000e+00 0.000000e+00</pose>
<parent>link_component_node-6__servo</parent>
<child>link_component_node-5__servo</child>
<axis><xyz>0.000000e+00 1.000000e+00 0.000000e+00</xyz>
<use_parent_model_frame>0</use_parent_model_frame>
<limit><lower>-7.853982e-01</lower>
<upper>7.853982e-01</upper>
<effort>1.765800e-01</effort>
<velocity>5.235988e+00</velocity></limit></axis></joint>
<joint type="revolute" name="joint_link_component_node-5__servo_link_component_node-0__box"><pose>6.409118e-02 2.120136e-03 3.009157e-20 -1.570796e+00 0.000000e+00 0.000000e+00</pose>
<parent>link_component_node-5__servo</parent>
<child>link_component_node-0__box</child>
<axis><xyz>0.000000e+00 1.000000e+00 0.000000e+00</xyz>
<use_parent_model_frame>0</use_parent_model_frame>
<limit><lower>-7.853982e-01</lower>
<upper>7.853982e-01</upper>
<effort>1.765800e-01</effort>
<velocity>5.235988e+00</velocity></limit></axis></joint>
<link name="link_component_node-9__frame"><pose>-1.141853e-01 -3.532095e-02 -2.082768e-17 0.000000e+00 -0.000000e+00 0.000000e+00</pose>
<visual name="component_node-9__frame_frame_visual"><pose>4.208530e-02 3.532095e-02 2.082768e-17 1.570796e+00 -0.000000e+00 0.000000e+00</pose>
<material><ambient>0.45 0.72 0.48 1.00</ambient><diffuse>0.45 0.72 0.48 1.00</diffuse><specular>0.1 0.1 0.1 1.00</specular></material>
<geometry><mesh><uri>model://rg_robot/meshes/ActiveHinge_Frame.dae</uri></mesh></geometry></visual>
<collision name="component_node-9__frame_collision"><pose>4.208530e-02 3.532095e-02 2.082768e-17 1.570796e+00 -0.000000e+00 0.000000e+00</pose>
<surface><contact><ode><kd>3.333333e+06</kd><kp>9.000000e+04</kp></ode></contact>
<friction><ode><mu>1.000000e+00</mu>
<mu2>1.000000e+00</mu2>
<slip1>1.000000e-02</slip1>
<slip2>1.000000e-02</slip2></ode>
<bullet><friction>1.000000e+00</friction>
<friction2>1.000000e+00</friction2></bullet></friction></surface>
<geometry><box><size>1.800000e-02 3.400000e-02 1.000000e-02</size></box></geometry></collision>
<visual name="component_node-9__root_visual"><pose>3.223530e-02 3.532095e-02 2.082768e-17 1.570796e+00 -0.000000e+00 0.000000e+00</pose>
<material><ambient>0.45 0.72 0.48 1.00</ambient><diffuse>0.45 0.72 0.48 1.00</diffuse><specular>0.1 0.1 0.1 1.00</specular></material>
<geometry><box><size>1.500000e-03 3.400000e-02 3.400000e-02</size></box></geometry></visual>
<collision name="component_node-9__root_collision"><pose>3.223530e-02 3.532095e-02 2.082768e-17 1.570796e+00 -0.000000e+00 0.000000e+00</pose>
<surface><contact><ode><kd>3.333333e+06</kd><kp>9.000000e+04</kp></ode></contact>
<friction><ode><mu>1.000000e+00</mu>
<mu2>1.000000e+00</mu2>
<slip1>1.000000e-02</slip1>
<slip2>1.000000e-02</slip2></ode>
<bullet><friction>1.000000e+00</friction>
<friction2>1.000000e+00</friction2></bullet></friction></surface>
<geometry><box><size>1.500000e-03 3.400000e-02 3.400000e-02</size></box></geometry></collision>
<visual name="component_node-10__box_visual"><pose>1.098530e-02 3.532095e-02 1.894222e-17 -9.197389e-17 -5.360631e-16 1.570796e+00</pose>
<material><ambient>0.45 0.72 0.48 1.00</ambient><diffuse>0.45 0.72 0.48 1.00</diffuse><specular>0.1 0.1 0.1 1.00</specular></material>
<geometry><mesh><uri>model://rg_robot/meshes/FixedBrick.dae</uri></mesh></geometry></visual>
<collision name="component_node-10__box_collision"><pose>1.098530e-02 3.532095e-02 1.894222e-17 -9.197389e-17 -5.360631e-16 1.570796e+00</pose>
<surface><contact><ode><kd>3.333333e+06</kd><kp>9.000000e+04</kp></ode></contact>
<friction><ode><mu>1.000000e+00</mu>
<mu2>1.000000e+00</mu2>
<slip1>1.000000e-02</slip1>
<slip2>1.000000e-02</slip2></ode>
<bullet><friction>1.000000e+00</friction>
<friction2>1.000000e+00</friction2></bullet></friction></surface>
<geometry><box><size>4.100000e-02 4.100000e-02 3.550000e-02</size></box></geometry></collision>
<visual name="component_node-11__box_visual"><pose>-3.001470e-02 3.532095e-02 8.733908e-18 -4.059924e-16 -8.500816e-16 1.570796e+00</pose>
<material><ambient>0.79 0.15 0.68 1.00</ambient><diffuse>0.79 0.15 0.68 1.00</diffuse><specular>0.1 0.1 0.1 1.00</specular></material>
<geometry><mesh><uri>model://rg_robot/meshes/FixedBrick.dae</uri></mesh></geometry></visual>
<collision name="component_node-11__box_collision"><pose>-3.001470e-02 3.532095e-02 8.733908e-18 -4.059924e-16 -8.500816e-16 1.570796e+00</pose>
<surface><contact><ode><kd>3.333333e+06</kd><kp>9.000000e+04</kp></ode></contact>
<friction><ode><mu>1.000000e+00</mu>
<mu2>1.000000e+00</mu2>
<slip1>1.000000e-02</slip1>
<slip2>1.000000e-02</slip2></ode>
<bullet><friction>1.000000e+00</friction>
<friction2>1.000000e+00</friction2></bullet></friction></surface>
<geometry><box><size>4.100000e-02 4.100000e-02 3.550000e-02</size></box></geometry></collision>
<visual name="component_node-12__box_visual"><pose>1.098530e-02 -5.679054e-03 -1.150906e-18 -4.440892e-16 -5.473822e-48 3.141593e+00</pose>
<material><ambient>0.18 0.13 0.85 1.00</ambient><diffuse>0.18 0.13 0.85 1.00</diffuse><specular>0.1 0.1 0.1 1.00</specular></material>
<geometry><mesh><uri>model://rg_robot/meshes/FixedBrick.dae</uri></mesh></geometry></visual>
<collision name="component_node-12__box_collision"><pose>1.098530e-02 -5.679054e-03 -1.150906e-18 -4.440892e-16 -5.473822e-48 3.141593e+00</pose>
<surface><contact><ode><kd>3.333333e+06</kd><kp>9.000000e+04</kp></ode></contact>
<friction><ode><mu>1.000000e+00</mu>
<mu2>1.000000e+00</mu2>
<slip1>1.000000e-02</slip1>
<slip2>1.000000e-02</slip2></ode>
<bullet><friction>1.000000e+00</friction>
<friction2>1.000000e+00</friction2></bullet></friction></surface>
<geometry><box><size>4.100000e-02 4.100000e-02 3.550000e-02</size></box></geometry></collision>
<visual name="component_node-13__box_visual"><pose>1.098530e-02 -4.667905e-02 -1.935856e-17 -4.440892e-16 -0.000000e+00 3.141593e+00</pose>
<material><ambient>0.50 0.65 0.96 1.00</ambient><diffuse>0.50 0.65 0.96 1.00</diffuse><specular>0.1 0.1 0.1 1.00</specular></material>
<geometry><mesh><uri>model://rg_robot/meshes/FixedBrick.dae</uri></mesh></geometry></visual>
<collision name="component_node-13__box_collision"><pose>1.098530e-02 -4.667905e-02 -1.935856e-17 -4.440892e-16 -0.000000e+00 3.141593e+00</pose>
<surface><contact><ode><kd>3.333333e+06</kd><kp>9.000000e+04</kp></ode></contact>
<friction><ode><mu>1.000000e+00</mu>
<mu2>1.000000e+00</mu2>
<slip1>1.000000e-02</slip1>
<slip2>1.000000e-02</slip2></ode>
<bullet><friction>1.000000e+00</friction>
<friction2>1.000000e+00</friction2></bullet></friction></surface>
<geometry><box><size>4.100000e-02 4.100000e-02 3.550000e-02</size></box></geometry></collision>
<visual name="component_node-14__box_visual"><pose>-3.001470e-02 -4.667905e-02 -2.391048e-17 2.220446e-16 2.220446e-16 -1.570796e+00</pose>
<material><ambient>0.25 0.93 0.90 1.00</ambient><diffuse>0.25 0.93 0.90 1.00</diffuse><specular>0.1 0.1 0.1 1.00</specular></material>
<geometry><mesh><uri>model://rg_robot/meshes/FixedBrick.dae</uri></mesh></geometry></visual>
<collision name="component_node-14__box_collision"><pose>-3.001470e-02 -4.667905e-02 -2.391048e-17 2.220446e-16 2.220446e-16 -1.570796e+00</pose>
<surface><contact><ode><kd>3.333333e+06</kd><kp>9.000000e+04</kp></ode></contact>
<friction><ode><mu>1.000000e+00</mu>
<mu2>1.000000e+00</mu2>
<slip1>1.000000e-02</slip1>
<slip2>1.000000e-02</slip2></ode>
<bullet><friction>1.000000e+00</friction>
<friction2>1.000000e+00</friction2></bullet></friction></surface>
<geometry><box><size>4.100000e-02 4.100000e-02 3.550000e-02</size></box></geometry></collision>
<inertial><mass>5.920000e-02</mass><inertia><ixx>9.443428e-05</ixx><ixy>-1.132213e-05</ixy><ixz>-1.047975e-20</ixz><iyy>4.479388e-05</iyy><iyz>-3.751743e-20</iyz><izz>1.269362e-04</izz></inertia></inertial>
<self_collide>True</self_collide></link>
<joint type="revolute" name="joint_link_component_node-0__box_link_component_node-9__frame"><pose>4.708530e-02 3.532095e-02 2.082768e-17 1.570796e+00 -0.000000e+00 0.000000e+00</pose>
<parent>link_component_node-0__box</parent>
<child>link_component_node-9__frame</child>
<axis><xyz>0.000000e+00 1.000000e+00 0.000000e+00</xyz>
<use_parent_model_frame>0</use_parent_model_frame>
<limit><lower>-7.853982e-01</lower>
<upper>7.853982e-01</upper>
<effort>1.765800e-01</effort>
<velocity>5.235988e+00</velocity></limit></axis></joint>
<plugin name="robot_controller" filename="libtolrobotcontrol.so"><rv:robot_config xmlns:rv="https://github.com/ElteHupkes/revolve"><rv:update_rate>8.000000e+00</rv:update_rate>
<rv:brain><rv:neuron layer="input" type="Input" id="node-0-in-0" part_id="node-0" />
<rv:neuron layer="input" type="Input" id="node-0-in-1" part_id="node-0" />
<rv:neuron layer="input" type="Input" id="node-0-in-2" part_id="node-0" />
<rv:neuron layer="input" type="Input" id="node-0-in-3" part_id="node-0" />
<rv:neuron layer="input" type="Input" id="node-0-in-4" part_id="node-0" />
<rv:neuron layer="input" type="Input" id="node-0-in-5" part_id="node-0" />
<rv:neuron layer="output" type="Simple" id="node-2-out-0" part_id="node-2"><rv:bias>0.000000e+00</rv:bias>
<rv:gain>5.000000e-01</rv:gain></rv:neuron>
<rv:neuron layer="output" type="Simple" id="node-3-out-0" part_id="node-3"><rv:bias>0.000000e+00</rv:bias>
<rv:gain>5.000000e-01</rv:gain></rv:neuron>
<rv:neuron layer="output" type="Simple" id="node-5-out-0" part_id="node-5"><rv:bias>0.000000e+00</rv:bias>
<rv:gain>5.000000e-01</rv:gain></rv:neuron>
<rv:neuron layer="output" type="Simple" id="node-6-out-0" part_id="node-6"><rv:bias>0.000000e+00</rv:bias>
<rv:gain>5.000000e-01</rv:gain></rv:neuron>
<rv:neuron layer="output" type="Simple" id="node-8-out-0" part_id="node-8"><rv:bias>0.000000e+00</rv:bias>
<rv:gain>5.000000e-01</rv:gain></rv:neuron>
<rv:neuron layer="output" type="Simple" id="node-9-out-0" part_id="node-9"><rv:bias>0.000000e+00</rv:bias>
<rv:gain>5.000000e-01</rv:gain></rv:neuron></rv:brain>
<rv:sensor link="link_component_node-0__box" sensor="node-0-imu_sensor" type="imu" id="node-0__node-0-imu_sensor" part_id="node-0" />
<rv:motor joint="joint_link_component_node-2__servo_link_component_node-0__box" type="position" id="node-2__rotate" part_id="node-2"><rv:pid><rv:p>9.000000e-01</rv:p>
<rv:i>0.000000e+00</rv:i>
<rv:d>0.000000e+00</rv:d>
<rv:i_max>0.000000e+00</rv:i_max>
<rv:i_min>0.000000e+00</rv:i_min></rv:pid></rv:motor>
<rv:motor joint="joint_link_component_node-2__servo_link_component_node-3__frame" type="position" id="node-3__rotate" part_id="node-3"><rv:pid><rv:p>9.000000e-01</rv:p>
<rv:i>0.000000e+00</rv:i>
<rv:d>0.000000e+00</rv:d>
<rv:i_max>0.000000e+00</rv:i_max>
<rv:i_min>0.000000e+00</rv:i_min></rv:pid></rv:motor>
<rv:motor joint="joint_link_component_node-5__servo_link_component_node-0__box" type="position" id="node-5__rotate" part_id="node-5"><rv:pid><rv:p>9.000000e-01</rv:p>
<rv:i>0.000000e+00</rv:i>
<rv:d>0.000000e+00</rv:d>
<rv:i_max>0.000000e+00</rv:i_max>
<rv:i_min>0.000000e+00</rv:i_min></rv:pid></rv:motor>
<rv:motor joint="joint_link_component_node-6__servo_link_component_node-5__servo" type="position" id="node-6__rotate" part_id="node-6"><rv:pid><rv:p>9.000000e-01</rv:p>
<rv:i>0.000000e+00</rv:i>
<rv:d>0.000000e+00</rv:d>
<rv:i_max>0.000000e+00</rv:i_max>
<rv:i_min>0.000000e+00</rv:i_min></rv:pid></rv:motor>
<rv:motor joint="joint_link_component_node-6__servo_link_component_node-8__frame" type="position" id="node-8__rotate" part_id="node-8"><rv:pid><rv:p>9.000000e-01</rv:p>
<rv:i>0.000000e+00</rv:i>
<rv:d>0.000000e+00</rv:d>
<rv:i_max>0.000000e+00</rv:i_max>
<rv:i_min>0.000000e+00</rv:i_min></rv:pid></rv:motor>
<rv:motor joint="joint_link_component_node-0__box_link_component_node-9__frame" type="position" id="node-9__rotate" part_id="node-9"><rv:pid><rv:p>9.000000e-01</rv:p>
<rv:i>0.000000e+00</rv:i>
<rv:d>0.000000e+00</rv:d>
<rv:i_max>0.000000e+00</rv:i_max>
<rv:i_min>0.000000e+00</rv:i_min></rv:pid></rv:motor>
<rv:battery><rv:level>0.000000e+00</rv:level></rv:battery></rv:robot_config></plugin>
<static>0</static></model></sdf>